[{"name": "unittest.loader._FailedTest.test.test_commute", "status": "errored", "message": "Failed to import test module: test.test_commute\nTraceback (most recent call last):\n  File \"/anaconda3/lib/python3.6/unittest/loader.py\", line 428, in _find_test_path\n    module = self._get_module_from_name(name)\n  File \"/anaconda3/lib/python3.6/unittest/loader.py\", line 369, in _get_module_from_name\n    __import__(name)\n  File \"/Users/satu/Kurssit/hy-data-analysis-with-python-spring-2019/part05-e09_commute/test/test_commute.py\", line 5, in <module>\n    import pandas as pd\n  File \"/anaconda3/lib/python3.6/site-packages/pandas/__init__.py\", line 55, in <module>\n    from ._version import get_versions\n  File \"<frozen importlib._bootstrap>\", line 971, in _find_and_load\n  File \"<frozen importlib._bootstrap>\", line 955, in _find_and_load_unlocked\n  File \"<frozen importlib._bootstrap>\", line 665, in _load_unlocked\n  File \"<frozen importlib._bootstrap_external>\", line 674, in exec_module\n  File \"<frozen importlib._bootstrap_external>\", line 771, in get_code\n  File \"<frozen importlib._bootstrap_external>\", line 441, in _validate_bytecode_header\nKeyboardInterrupt\n", "passed": false, "points": [], "backtrace": ["  File \"/anaconda3/lib/python3.6/unittest/case.py\", line 59, in testPartExecutor\n    yield\n", "  File \"/anaconda3/lib/python3.6/unittest/case.py\", line 605, in run\n    testMethod()\n", "  File \"/anaconda3/lib/python3.6/unittest/loader.py\", line 34, in testFailure\n    raise self._exception\n"]}]